Workbook
Name \0: #REF!
Name \0: #REF!
Name \0: #REF!
Name \0: #REF!
Name \0: #REF!
Name \0: #REF!
Name \a: #REF!
Name \a: #REF!
Name \a: #REF!
Name \a: #REF!
Name \a: #REF!
Name \a: #REF!
Name \a: #REF!
Name \aa: #REF!
Name \aa: #REF!
Name \aa: #REF!
Name \aa: #REF!
Name \aa: #REF!
Name \aa: #REF!
Name \aa: #REF!
Name \b: #REF!
Name \b: #REF!
Name \b: #REF!
Name \b: #REF!
Name \b: #REF!
Name \b: #REF!
Name \b: #REF!
Name \c: #REF!
Name \c: #REF!
Name \c: #REF!
Name \c: #REF!
Name \c: #REF!
Name \c: #REF!
Name \c: #REF!
Name \d: #REF!
Name \d: #REF!
Name \d: #REF!
Name \d: #REF!
Name \d: #REF!
Name \d: #REF!
Name \d: #REF!
Name \e: #REF!
Name \e: #REF!
Name \e: #REF!
Name \e: #REF!
Name \e: #REF!
Name \e: #REF!
Name \e: #REF!
Name \f: #REF!
Name \f: #REF!
Name \f: #REF!
Name \f: #REF!
Name \f: #REF!
Name \f: #REF!
Name \f: #REF!
Name \g: #REF!
Name \g: #REF!
Name \g: #REF!
Name \g: #REF!
Name \g: #REF!

Sheet Unit Cost
A1: Project Name: | B1: ELM5 | X1: v0.1 | Z1: True Cost | AA1: True Cost | AC1: True Cost | AD1: True Cost | AF1: True Cost | AG1: True Cost | AI1: True Cost | AJ1: True Cost | AL1: True Cost | AM1: True Cost | AN1: True Cost | AO1: True Cost
A2: Supplier name: | B2: Foxlink | X2: 43467
Z3: 9/18/2023 | AA3: 4/10/2023 | AC3: 9/18/2023 | AD3: 4/10/2023 | AF3: 9/18/2023 | AG3: 4/10/2023 | AI3: 9/18/2023 | AJ3: 4/10/2023 | AL3: 12/2/22 | AM3: 9/13/22 | AN3: 9/5/22 | AO3: 4/12/22
Z4: 350k | AA4: 350k | AC4: 350k | AD4: 350k | AF4: 350k | AG4: 350k | AI4: 350k | AJ4: 350k | AL4: 350k | AM4: 350k | AN4: 350k | AO4: 350k
A5: Retail Packaging | D5: Made In China | E5: Made In Vietnam | F5: Made in Taiwan | G5: Made In China | H5: Made In Vietnam | I5: Made in Taiwan | J5: Made In China | K5: Made In Vietnam | L5: Made in Taiwan | M5: Made In China | N5: Made In Vietnam | O5: Made in Taiwan | P5: Made In China | Q5: Made In Vietnam | R5: Made in Taiwan | T5: Made In China | U5: Made In Myanmar | V5: Made In China | W5: Made In Myanmar | Z5: Made In China | AA5: Made In Vietnam | AB5: Made in Taiwan | AC5: Made In China | AD5: Made In Vietnam | AE5: Made in Taiwan | AF5: Made In China | AG5: Made In Vietnam | AH5: Made in Taiwan | AI5: Made In China | AJ5: Made In Vietnam | AK5: Made in Taiwan
D6: Option A | E6: Option B | F6: Option C | G6: Option A | H6: Option B | I6: Option C | J6: Option A | K6: Option B | L6: Option C | M6: Option A | N6: Option B | O6: Option C | P6: Option A | Q6: Option B | R6: Option C | T6: Option A | U6: Option A | V6: Option A | W6: Option A | Z6: Option A | AA6: Option B | AB6: Opttion C | AC6: Option A | AD6: Option B | AE6: Opttion C | AF6: Option A | AG6: Option B | AH6: Opttion C | AI6: Option A | AJ6: Option B | AK6: Opttion C | AL6: Remark
D7: 45622 | E7: =D7 -> 45622 | F7: =E7 -> 45622 | G7: 45608 | H7: =G7 -> 45608 | I7: =H7 -> 45608 | J7: 45504 | K7: =J7 -> 45504 | L7: =K7 -> 45504 | M7: 45461 | N7: 45461 | O7: 45461 | P7: 45350 | Q7: 45364 | R7: 45364 | T7: 44861 | U7: 44861 | V7: 44413 | W7: 44413 | Z7: 45622 | AA7: 45622 | AB7: 45622 | AC7: 45608 | AD7: 45608 | AE7: 45608 | AF7: 45461 | AG7: 45461 | AH7: 45461 | AI7: 45350 | AJ7: 45364 | AK7: 45364
A8: Rival 3 Gen2 Quote | D8: CMF v1.2, Remove internal LED lens and etch for SS logo, replace with painted logo | E8: CMF v1.2, Remove internal LED lens and etch for SS logo, replace with painted logo | F8: CMF v1.2, Remove internal LED lens and etch for SS logo, replace with painted logo | G8: CMF v1.2, Remove internal LED lens and etch for SS logo, replace with painted logo | H8: CMF v1.2, Remove internal LED lens and etch for SS logo, replace with painted logo | I8: CMF v1.2, Remove internal LED lens and etch for SS logo, replace with painted logo | J8: CMF v1.2, Remove internal LED lens and etch for SS logo, replace with painted logo | K8: CMF v1.2, Remove internal LED lens and etch for SS logo, replace with painted logo | L8: CMF v1.2, Remove internal LED lens and etch for SS logo, replace with painted logo | M8: CMF v1.2, Remove internal LED lens and etch for SS logo, replace with painted logo | N8: CMF v1.2, Remove internal LED lens and etch for SS logo, replace with painted logo | O8: CMF v1.2, Remove internal LED lens and etch for SS logo, replace with painted logo | P8: CMF v1.2, Remove internal LED lens and etch for SS logo, replace with painted logo | Q8: CMF v1.2, Remove internal LED lens and etch for SS logo, replace with painted logo | R8: CMF v1.2, Remove internal LED lens and etch for SS logo, replace with painted logo | T8: CMFv2_6LEDs 3 Zones + Logo LED current control by each one | U8: CMFv2_6LEDs 3 Zones + Logo LED current control by each one | V8: CMFv2_6LEDs 3 Zones + Logo LED current control by each one | W8: CMFv2_6LEDs 3 Zones + Logo LED current control by each one | Z8: CMF v1.2, Remove internal LED lens and etch for SS logo, replace with painted logo | AA8: CMF v1.2, Remove internal LED lens and etch for SS logo, replace with painted logo | AB8: CMF v1.2, Remove internal LED lens and etch for SS logo, replace with painted logo | AC8: CMF v1.2, Remove internal LED lens and etch for SS logo, replace with painted logo | AD8: CMF v1.2, Remove internal LED lens and etch for SS logo, replace with painted logo | AE8: CMF v1.2, Remove internal LED lens and etch for SS logo, replace with painted logo | AF8: CMF v1.2, Remove internal LED lens and etch for SS logo, replace with painted logo | AG8: CMF v1.2, Remove internal LED lens and etch for SS logo, replace with painted logo | AH8: CMF v1.2, Remove internal LED lens and etch for SS logo, replace with painted logo | AI8: CMF v1.2, Remove internal LED lens and etch for SS logo, replace with painted logo | AJ8: CMF v1.2, Remove internal LED lens and etch for SS logo, replace with painted logo | AK8: CMF v1.2, Remove internal LED lens and etch for SS logo, replace with painted logo
D9: Quote Based Quantity : 418Kpcs/year | E9: Quote Based Quantity : 418Kpcs/year | F9: Quote Based Quantity : 150Kpcs/year(only for US) | G9: Quote Based Quantity : 418Kpcs/year | H9: Quote Based Quantity : 418Kpcs/year | I9: Quote Based Quantity : 150Kpcs/year(only for US) | J9: Quote Based Quantity : 418Kpcs/year | K9: Quote Based Quantity : 418Kpcs/year | L9: Quote Based Quantity : 150Kpcs/year(only for US) | M9: Quote Based Quantity : 418Kpcs/year | N9: Quote Based Quantity : 418Kpcs/year | O9: Quote Based Quantity : 150Kpcs/year(only for US) | P9: Quote Based Quantity : 418Kpcs/year | Q9: Quote Based Quantity : 418Kpcs/year | R9: Quote Based Quantity : 150Kpcs/year(only for US) | T9: Quote Based Quantity : 250Kpcs/year | U9: Quote Based Quantity : 250Kpcs/year | V9: Quote Based Quantity : 250Kpcs/year | W9: Quote Based Quantity : 250Kpcs/year | Z9: Quote Based Quantity : 418Kpcs/year | AA9: Quote Based Quantity : 418Kpcs/year | AB9: Quote Based Quantity : 150Kpcs/year(only for US) | AC9: Quote Based Quantity : 418Kpcs/year | AD9: Quote Based Quantity : 418Kpcs/year | AE9: Quote Based Quantity : 150Kpcs/year(only for US) | AF9: Quote Based Quantity : 418Kpcs/year | AG9: Quote Based Quantity : 418Kpcs/year | AH9: Quote Based Quantity : 150Kpcs/year(only for US) | AI9: Quote Based Quantity : 418Kpcs/year | AJ9: Quote Based Quantity : 418Kpcs/year | AK9: Quote Based Quantity : 150Kpcs/year(only for US)
D10: Per Unit Price | E10: Per Unit Price | F10: Per Unit Price | G10: Per Unit Price | H10: Per Unit Price | I10: Per Unit Price | J10: Per Unit Price | K10: Per Unit Price | L10: Per Unit Price | M10: Per Unit Price | N10: Per Unit Price | O10: Per Unit Price | P10: Per Unit Price | Q10: Per Unit Price | R10: Per Unit Price | T10: Per Unit Price | U10: Per Unit Price | V10: Per Unit Price | W10: Per Unit Price | Z10: Per Unit Price | AA10: Per Unit Price | AB10: Per Unit Price | AC10: Per Unit Price | AD10: Per Unit Price | AE10: Per Unit Price | AF10: Per Unit Price | AG10: Per Unit Price | AH10: Per Unit Price | AI10: Per Unit Price | AJ10: Per Unit Price | AK10: Per Unit Price
A11: CDM | D11: SKU Total in US$ | E11: SKU Total in US$ | F11: SKU Total in US$ | G11: SKU Total in US$ | H11: SKU Total in US$ | I11: SKU Total in US$ | J11: SKU Total in US$ | K11: SKU Total in US$ | L11: SKU Total in US$ | M11: SKU Total in US$ | N11: SKU Total in US$ | O11: SKU Total in US$ | P11: SKU Total in US$ | Q11: SKU Total in US$ | R11: SKU Total in US$ | T11: SKU Total in US$ | U11: SKU Total in US$ | V11: SKU Total in US$ | W11: SKU Total in US$ | X11: Remarks
A12: EE (Black) | D12: =G12 -> 6.017395 | E12: =D12*1.0381 -> 6.2466577 | F12: =D12 -> 6.017395 | G12: =J12 -> 6.017395 | H12: =K12 -> 6.2466577 | I12: =H12 -> 6.2466577 | J12: =M12 -> 6.017395 | K12: =N12 -> 6.2466577 | L12: =K12 -> 6.2466577 | M12: =P12 -> 6.017395 | N12: =Q12 -> 6.2466577 | O12: =N12 -> 6.2466577 | P12: ='EE bom 0227'!T168 -> 6.017395 | Q12: =P12*1.0381 -> 6.2466577 | R12: =Q12 -> 6.2466577 | S12: EE | T12: 5.686775 | U12: 5.9034411 | V12: 5.736775 | W12: 5.9553461 | Z12: ='EE bom 0227'!Z168 -> 5.39273 | AA12: =Z12*1.0381 -> 5.598193 | AB12: =Z12 -> 5.39273 | AC12: ='EE bom 0227'!Z168 -> 5.39273 | AD12: =AC12 -> 5.39273 | AE12: =AC12 -> 5.39273 | AF12: =AI12 -> 5.39273 | AG12: =AF12 -> 5.39273 | AH12: =AF12 -> 5.39273 | AI12: ='EE bom 0227'!Z168 -> 5.39273 | AJ12: =AI12 -> 5.39273 | AK12: =AI12 -> 5.39273 | AL12: 031324: for VN & TW, refer to ELM5 quote, added 3%
A13: EE (White) | D13: =G13 -> 6.088895 | E13: =D13*1.0381 -> 6.3208819 | F13: =D13 -> 6.088895 | G13: =J13 -> 6.088895 | H13: =G13*1.0381 -> 6.3208819 | I13: =H13 -> 6.3208819 | J13: =M13 -> 6.088895 | K13: =J13*1.0381 -> 6.3208819 | L13: =K13 -> 6.3208819 | M13: =P13 -> 6.088895 | N13: =M13*1.0381 -> 6.3208819 | O13: =N13 -> 6.3208819 | P13: ='EE bom 0227'!T169 -> 6.088895 | Q13: =P13*1.0381 -> 6.3208819 | R13: =Q13 -> 6.3208819 | S13: ME | T13: 3.3938138 | U13: 3.5231182 | V13: 3.5238138 | W13: 3.6580712 | Z13: ='EE bom 0227'!Z169 -> 5.44973 | AA13: =Z13*1.0381 -> 5.6573647 | AB13: =Z13 -> 5.44973 | AC13: ='EE bom 0227'!Z169 -> 5.44973 | AD13: =AC13 -> 5.44973 | AE13: =AC13 -> 5.44973 | AF13: =AI13 -> 5.44973 | AG13: =AF13 -> 5.44973 | AH13: =AF13 -> 5.44973 | AI13: ='EE bom 0227'!Z169 -> 5.44973 | AJ13: =AI13 -> 5.44973 | AK13: =AI13 -> 5.44973 | AL13: 031324: for VN & TW, refer to ELM5 quote, added 3%
A14: ME (Black) | D14: =G14 -> 1.6713398 | E14: =D14*1.0381 -> 1.7350179 | F14: =D14 -> 1.6713398 | G14: =J14 -> 1.6713398 | H14: =G14*1.0381 -> 1.7350179 | I14: =H14 -> 1.7350179 | J14: =M14 -> 1.6713398 | K14: =J14*1.0381 -> 1.7350179 | L14: =K14 -> 1.7350179 | M14: ='ME bom 0618_Black'!V29 -> 1.6713398 | N14: =M14*1.0381 -> 1.7350179 | O14: =N14 -> 1.7350179 | P14: ='ME bom 0229_Black'!V29 -> 1.5898038 | Q14: =P14*1.0381 -> 1.6503754 | R14: =Q14 -> 1.6503754 | S14: Packaging | T14: 0.67444804 | U14: 0.70014451 | V14: 0.67444804 | W14: 0.70014451 | X14: 6/18 Update light-guide, bottom cover material as Rival3 Gen1 light-guide. | Z14: ='ME bom 0618_Black'!AD29 -> 1.6309795 | AA14: =Z14*1.0381 -> 1.6931198 | AB14: =Z14 -> 1.6309795 | AC14: ='ME bom 0618_Black'!AD29 -> 1.6309795 | AD14: =AC14 -> 1.6309795 | AE14: =AC14 -> 1.6309795 | AF14: ='ME bom 0618_Black'!AD29 -> 1.6309795 | AG14: =AF14 -> 1.6309795 | AH14: =AF14 -> 1.6309795 | AI14: ='ME bom 0229_Black'!AD29 -> 1.4185819 | AJ14: =AI14 -> 1.4185819 | AK14: =AI14 -> 1.4185819 | AL14: 031324: for VN & TW, refer to ELM5 quote, added 3% 022924: w/o the true cost of SIDE BUTTON, CPI BUTTON, WHEEL HUB, SWITCH CUSHION, LED CLIP
A15: ME (White) | D15: =G15 -> 1.815194 | E15: =D15*1.0381 -> 1.8843529 | F15: =D15 -> 1.815194 | G15: =J15 -> 1.815194 | H15: =G15*1.0381 -> 1.8843529 | I15: =H15 -> 1.8843529 | J15: =M15 -> 1.815194 | K15: =J15*1.0381 -> 1.8843529 | L15: =K15 -> 1.8843529 | M15: ='ME bom 0618_White'!V29 -> 1.815194 | N15: =M15*1.0381 -> 1.8843529 | O15: =N15 -> 1.8843529 | P15: ='ME bom 0229_White'!V29 -> 1.6993808 | Q15: =P15*1.0381 -> 1.7641272 | R15: =Q15 -> 1.7641272 | S15: MVA | T15: 1.25 | U15: 1.195 | V15: 1.25 | W15: 1.195 | X15: 6/18 Correction of incorrect price for light-guide. | Z15: ='ME bom 0618_White'!AD29 -> 1.7058044 | AA15: =Z15*1.0381 -> 1.7707955 | AB15: =Z15 -> 1.7058044 | AC15: ='ME bom 0618_White'!AD29 -> 1.7058044 | AD15: =AC15 -> 1.7058044 | AE15: =AC15 -> 1.7058044 | AF15: ='ME bom 0618_White'!AD29 -> 1.7058044 | AG15: =AF15 -> 1.7058044 | AH15: =AF15 -> 1.7058044 | AI15: ='ME bom 0229_White'!AD29 -> 1.5403829 | AJ15: =AI15 -> 1.5403829 | AK15: =AI15 -> 1.5403829 | AL15: 031324: for VN & TW, refer to ELM5 quote, added 3% 022924: w/o the true cost of SWITCH CUSHION, LED CLIP.
A16: Packaging | D16: =G16 -> 0.82809498 | E16: ='PKG BOM 20241119-TW'!M32 -> 0.94416822 | F16: =E16 -> 0.94416822 | G16: ='PKG BOM 20241023_Amber'!M32 -> 0.82809498 | H16: =G16*1.0381 -> 0.8596454 | I16: =H16 -> 0.8596454 | J16: ='PKG BOM 20240731_with FSC&減塑'!L36 -> 0.82839065 | K16: =J16*1.0381 -> 0.85995234 | L16: =K16 -> 0.85995234 | M16: ='PKG BOM 20240618_with FSC&減塑'!L35 -> 1.1086137 | N16: =M16*1.0381 -> 1.1508518 | O16: =N16 -> 1.1508518 | P16: ='PKG BOM 20240308_with FSC'!N35 -> 0.73168367 | Q16: =P16*1.0381 -> 0.75956082 | R16: =Q16 -> 0.75956082 | S16: PRIME COST (Matl + Labor): | T16: 11.005037 | U16: 11.321704 | V16: 11.185037 | W16: 11.508562 | X16: 11/26 Update PKG TW cost for PID & manual. 11/12 Update PKG BOM 7/31 Paper bag chage to Tissue Wrap 6/18 Update PKG price for Plastic Reduction. | Z16: ='PKG BOM 20241023_Amber'!X32 -> 0.70605015 | AA16: ='PKG BOM 20241119-TW'!AA32 -> 0.79625336 | AB16: =AA16 -> 0.79625336 | AC16: ='PKG BOM 20241023_Amber'!X32 -> 0.70605015 | AD16: =AC16 -> 0.70605015 | AE16: =AC16 -> 0.70605015 | AF16: ='PKG BOM 20240618_with FSC&減塑'!T35 -> 0.79299221 | AG16: =AF16 -> 0.79299221 | AH16: =AF16 -> 0.79299221 | AI16: ='PKG BOM 20240308_with FSC'!V35 -> 0.47463541 | AJ16: =AI16 -> 0.47463541 | AK16: =AI16 -> 0.47463541 | AL16: 031324: for VN & TW, refer to ELM5 quote, added 3%
A17: Black Material Cost | D17: =D12+D14+D16 -> 8.5168298 | E17: =E12+E14+E16 -> 8.9258439 | F17: =F12+F14+F16 -> 8.6329031 | G17: =G12+G14+G16 -> 8.5168298 | H17: =H12+H14+H16 -> 8.841321 | I17: =H17 -> 8.841321 | J17: =J12+J14+J16 -> 8.5171255 | K17: =K12+K14+K16 -> 8.841628 | L17: =K17 -> 8.841628 | M17: =M12+M14+M16 -> 8.7973485 | N17: =N12+N14+N16 -> 9.1325275 | O17: =N17 -> 9.1325275 | P17: =P12+P14+P16 -> 8.3388825 | Q17: =Q12+Q14+Q16 -> 8.6565939 | R17: =Q17 -> 8.6565939
A18: White Material Cost | D18: =D13+D15+D16 -> 8.7321839 | E18: =E13+E15+E16 -> 9.149403 | F18: =F13+F15+F16 -> 8.8482572 | G18: =G13+G15+G16 -> 8.7321839 | H18: =H13+H15+H16 -> 9.0648801 | I18: =H18 -> 9.0648801 | J18: =J13+J15+J16 -> 8.7324796 | K18: =K13+K15+K16 -> 9.0651871 | L18: =K18 -> 9.0651871 | M18: =M13+M15+M16 -> 9.0127026 | N18: =N13+N15+N16 -> 9.3560866 | O18: =N18 -> 9.3560866 | P18: =P13+P15+P16 -> 8.5199595 | Q18: =Q13+Q15+Q16 -> 8.8445699 | R18: =Q18 -> 8.8445699
A19: MVA | D19: 1.8558 | E19: 1.43 | F19: 3.207 | G19: 1.8558 | H19: 1.43 | I19: =2.84+0.1634 -> 3.0034 | J19: 1.8558 | K19: 1.43 | L19: =2.84+0.1634 -> 3.0034 | M19: 1.8558 | N19: 1.43 | O19: =2.84+0.1634 -> 3.0034 | P19: 1.8558 | Q19: 1.43 | R19: =2.84+0.1634 -> 3.0034 | S19: SG&A +Profit | T19: 0.75 | U19: 0.75 | V19: 0.75 | W19: 0.75 | Y19: MVA | Z19: 1.8517403 | AA19: =0.5+0.93+0.3 -> 1.73 | AB19: =0.38+1.29+1.17 -> 2.84 | AC19: 1.8517403 | AD19: =0.5+0.93+0.3 -> 1.73 | AE19: =0.38+1.29+1.17 -> 2.84 | AF19: 1.8517403 | AG19: =0.5+0.93+0.3 -> 1.73 | AH19: =0.38+1.29+1.17 -> 2.84 | AI19: 1.8517403 | AJ19: =0.5+0.93+0.3 -> 1.73 | AK19: =0.38+1.29+1.17 -> 2.84 | AL19: 031324: for VN, labor rate is 2.67 for TW, labor rate is 8.64 Produced in TW is based on SMT and pre assemblled in FD then assembly in TW
A20: PRIME COST (Matl + Labor): Black ver. | D20: =D17+D19 -> 10.37263 | E20: =E17+E19 -> 10.355844 | F20: =F17+F19 -> 11.839903 | G20: =G17+G19 -> 10.37263 | H20: =H17+H19 -> 10.271321 | I20: =I17+I19 -> 11.844721 | J20: =J17+J19 -> 10.372925 | K20: =K17+K19 -> 10.271628 | ... R20: =R17+R19 -> 11.659994 | S20: Total Cost (Ex-Factory): | T20: 11.755037 | U20: 12.071704 | V20: 11.935037 | W20: 12.258562 | Y20: Material Black | Z20: =Z12+Z14+Z16 -> 7.7297596 | AA20: =AA12+AA14+AA16 -> 8.0875662 | AB20: =AB12+AB14+AB16 -> 7.8199628 | AC20: =AC12+AC14+AC16 -> 7.7297596 | AD20: =AD12+AD14+AD16 -> 7.7297596 | AE20: =AE12+AE14+AE16 -> 7.7297596 | AF20: =AF12+AF14+AF16 -> 7.8167017 | AG20: =AG12+AG14+AG16 -> 7.8167017 | ... AK20: =AK12+AK14+AK16 -> 7.2859473
A21: PRIME COST (Matl + Labor): White ver. | D21: =D18+D19 -> 10.587984 | E21: =E18+E19 -> 10.579403 | F21: =F18+F19 -> 12.055257 | G21: =G18+G19 -> 10.587984 | H21: =H18+H19 -> 10.49488 | I21: =I18+I19 -> 12.06828 | J21: =J18+J19 -> 10.58828 | K21: =K18+K19 -> 10.495187 | ... R21: =R18+R19 -> 11.84797 | T21: Effective from Nov 1. 2022(new PO) | V21: Effective from Oct 1. 2021 | Y21: Material White | Z21: =Z13+Z15+Z16 -> 7.8615846 | AA21: =AA13+AA15+AA16 -> 8.2244136 | AB21: =AB13+AB15+AB16 -> 7.9517878 | AC21: =AC13+AC15+AC16 -> 7.8615846 | AD21: =AD13+AD15+AD16 -> 7.8615846 | AE21: =AE13+AE15+AE16 -> 7.8615846 | AF21: =AF13+AF15+AF16 -> 7.9485266 | AG21: =AG13+AG15+AG16 -> 7.9485266 | ... AK21: =AK13+AK15+AK16 -> 7.4647483
A22: SG&A +Profit | D22: 0.75 | E22: 0.75 | F22: 0.75 | G22: 0.75 | H22: 0.75 | I22: 0.75 | J22: 0.75 | K22: 0.75 | L22: 0.75 | M22: 0.75 | N22: 0.75 | O22: 0.75 | P22: 0.75 | Q22: 0.75 | R22: 0.75 | Z22: 0.75 | AA22: 0.75 | AB22: 0.75 | AC22: 0.75 | AD22: 0.75 | AE22: 0.75 | AF22: 0.75 | AG22: 0.75 | AH22: 0.75 | AI22: 0.75 | AJ22: 0.75 | AK22: 0.75
A23: Total Cost (Ex-Factory): Black ver. | D23: =SUM(D20,D22) -> 11.12263 | E23: =SUM(E20,E22) -> 11.105844 | F23: =SUM(F20,F22) -> 12.589903 | G23: =SUM(G20,G22) -> 11.12263 | H23: =SUM(H20,H22) -> 11.021321 | I23: =SUM(I20,I22) -> 12.594721 | J23: =SUM(J20,J22) -> 11.122925 | K23: =SUM(K20,K22) -> 11.021628 | ... R23: =SUM(R20,R22) -> 12.409994 | Y23: Material Black + MVA | Z23: =Z20+Z19 -> 9.5814999 | AA23: =AA20+AA19 -> 9.8175662 | AB23: =AB20+AB19 -> 10.659963 | AC23: =AC20+AC19 -> 9.5814999 | AD23: =AD20+AD19 -> 9.4597596 | AE23: =AE20+AE19 -> 10.56976 | AF23: =AF20+AF19 -> 9.668442 | AG23: =AG20+AG19 -> 9.5467017 | ... AK23: =AK20+AK19 -> 10.125947
A24: Total Cost (Ex-Factory): White ver. | D24: =SUM(D21,D22) -> 11.337984 | E24: =SUM(E21,E22) -> 11.329403 | F24: =SUM(F21,F22)-0.055 -> 12.750257 | G24: =SUM(G21,G22) -> 11.337984 | H24: =SUM(H21,H22) -> 11.24488 | I24: =SUM(I21,I22) -> 12.81828 | J24: =SUM(J21,J22) -> 11.33828 | K24: =SUM(K21,K22) -> 11.245187 | L24: =SUM(L21,L22) -> 12.818587 | M24: =SUM(M21,M22) -> 11.618503 | N24: =SUM(N21,N22) -> 11.536087 | ... R24: =SUM(R21,R22) -> 12.59797 | Y24: Material White + MVA | Z24: =Z21+Z19 -> 9.7133249 | AA24: =AA21+AA19 -> 9.9544136 | AB24: =AB21+AB19 -> 10.791788 | AC24: =AC21+AC19 -> 9.7133249 | AD24: =AD21+AD19 -> 9.5915846 | AE24: =AE21+AE19 -> 10.701585 | AF24: =AF21+AF19 -> 9.8002669 | AG24: =AG21+AG19 -> 9.6785266 | ... AK24: =AK21+AK19 -> 10.304748
Y25: Material margin (black) | Z25: =(G23-(Z12+Z14+Z16))/G23 -> 0.30504209 | AA25: =(H23-(AA12+AA14+AA16))/H23 -> 0.26618904 | AB25: =(I23-(AB12+AB14+AB16))/I23 -> 0.3791079 | AC25: =(J23-(AC12+AC14+AC16))/J23 -> 0.30506056 | AD25: =(K23-(AD12+AD14+AD16))/K23 -> 0.29867351 | AE25: =(L23-(AE12+AE14+AE16))/L23 -> 0.38628484 | AF25: =(M23-(AF12+AF14+AF16))/M23 -> 0.31451373 | AG25: =(N23-(AG12+AG14+AG16))/N23 -> 0.30902252 | ... AK25: =(R23-(AK12+AK14+AK16))/R23 -> 0.41289679
Y26: Gross margin (black) | Z26: =(D23-Z23)/D23 -> 0.13855805 | AA26: =(H23-AA23)/H23 -> 0.10922056 | AB26: =(I23-AB23)/I23 -> 0.1536166 | AC26: =(G23-AC23)/G23 -> 0.13855805 | AD26: =(K23-AD23)/K23 -> 0.14170941 | AE26: =(L23-AE23)/L23 -> 0.16079904 | AF26: =(M23-AF23)/M23 -> 0.15212522 | AG26: =(N23-AG23)/N23 -> 0.15609472 | AH26: =(O23-AH23)/O23 -> 0.17299692 | AI26: =(P23-AI23)/P23 -> 0.16510254 | AJ26: =(Q23-AJ23)/Q23 -> 0.16800912 | AK26: =(R23-AK23)/R23 -> 0.18404897
Y27: Material margin (white) | Z27: =(G24-(Z13+Z15+Z16))/G24 -> 0.3066153 | AA27: =(H24-(AA13+AA15+AA16))/H24 -> 0.26860816 | AB27: =(I24-(AB13+AB15+AB16))/I24 -> 0.37965252 | AC27: =(J24-(AC13+AC15+AC16))/J24 -> 0.30663339 | AD27: =(K24-(AD13+AD15+AD16))/K24 -> 0.3008934 | AE27: =(L24-(AE13+AE15+AE16))/L24 -> 0.38670428 | AF27: =(M24-(AF13+AF15+AF16))/M24 -> 0.31587341 | AG27: =(N24-(AG13+AG15+AG16))/N24 -> 0.31098587 | ... AK27: =(R24-(AK13+AK15+AK16))/R24 -> 0.40746419
Y28: Gross margin (white) | Z28: =(D24-Z24)/D24 -> 0.14329347 | AA28: =(H24-AA24)/H24 -> 0.11476036 | AB28: =(I24-AB24)/I24 -> 0.15809394 | AC28: =(G24-AC24)/G24 -> 0.14329347 | AD28: =(K24-AD24)/K24 -> 0.1470498 | AE28: =(L24-AE24)/L24 -> 0.165151 | AF28: =(M24-AF24)/M24 -> 0.15649484 | AG28: =(N24-AG24)/N24 -> 0.16102167 | AH28: =(O24-AH24)/O24 -> 0.17704431 | AI28: =(P24-AI24)/P24 -> 0.16261999 | AJ28: =(Q24-AJ24)/Q24 -> 0.16597669 | AK28: =(R24-AK24)/R24 -> 0.18203104
AC29: =AC20/J23 -> 0.69493944 | AF29: =AF20/M23 -> 0.68548627 | AI29: =AI20/P23 -> 0.66570659
AC30: =AC19/J23 -> 0.16647961 | AF30: =AF19/M23 -> 0.16238851 | AI30: =AI19/P23 -> 0.16919087

Sheet PKG BOM 20241119-TW
R1: 裕同 | S1: 旺盈 | V1: FD | X1: TW
A2: Steelseries Rival3 Gen2 RFQ - Package BOM list | M2: Date: 2024/6/18 | Q2: True Cost | AC2: True Cost | AJ2: 7.1
A3: Model Description: Steelseries Rival 3 Gen2 | K3: Rev.:A | L3: ELM5 Gen2 | P3: Difference between 1015 & 0618 | Q3: 2024/10/14 DV Phase | R3: 報價 in RMB w/ FSC certificate | V3: 報價 in USD w/ FSC certificate | X3: 報價 in USD w/ FSC certificate | AB3: Markup | AC3: EV Phase | AD3: 報價 in RMB w/ FSC certificate | AG3: 報價 in USD w/ FSC certificate | AI3: Markup | AJ3: Remark
A4: No. | B4: Level | C4: Foxlink P/N | D4: Foxlink P/N description | E4: Customer P/N | F4: Customer Description | H4: Image | I4: Description | J4: Chinese Part name | K4: Unit Q'ty (pcs) | L4: Unit Price (USD/pc) ELM5 Gen2 | M4: Amount (USD) ELM5 Gen2 | N4: Remark | Q4: QTY | R4: 單價 RMB | S4: 單價 RMB | T4: MOQ | U4: LT day | V4: 單價 USD | W4: Amount(USD) | X4: MOQ | Y4: LT day | Z4: 單價 USD | AA4: Amount(USD) | AC4: QTY | AD4: 單價 RMB | AE4: MOQ | AF4: LT day | AG4: 單價 USD | AH4: Amount(USD)
A5: 1 | B5: 1 | C5: 584A-1053-00A0 | D5: BOX,ELM5 Gen2/FSG-E1J7,62515 RIVAL3 GEN2 BLACK, 153x86x46mm,300gsm SBS,FSC,RoHS | E5: N/A | F5: black Box | G5: material: 300g artpaper, 4C+1C PMS, printing: matte PP dimension：278x250mm | I5: Box Outside set-up dimensions:(LxWxD):153x86x46mm Flat sheet dimensions:(L)278x(W)250x(T)0.5mm Material:350gsm SBS Print: 4C+1C PMS Surface process: AQ Coating Joint: Glued inside Remark:包装原料需符合FSC认证要求 | J5: 彩盒 | K5: 1 | L5: 0.3033 | M5: =L5*K5 -> 0.3033 | N5: 031324: Paper with FSC certificate was 0.2821 | P5: =W5-AH5 -> 0.053561368 | Q5: 1 | R5: 1.42 | S5: 1.4 | T5: 5000 | U5: =AF5 -> 14 | V5: 0.20285714 | W5: =V5*K5 -> 0.20285714 | X5: 5000 | Z5: =V5 -> 0.20285714 | AA5: =Z5*K5 -> 0.20285714 | AB5: =(M5-W5)/W5 -> 0.49514085 | AC5: 1 | AD5: 1.06 | AE5: 5000 | AF5: 14 | AG5: =AD5/$AJ$2 -> 0.14929577 | AH5: =AG5*K5 -> 0.14929577 | AI5: =(L5-AG5)/AG5 -> 1.0315377 | AJ5: difference between FSC and w/o FSC
A6: 2 | C6: 5831-1053-00A0 | D6: CARD,ELM5 Gen2/FSG-E1J7,HANG TAB,350GSM SBS DOUBLE,AQ COATING,FSC,RoHS | E6: N/A | F6: Hanger | I6: Hang tab Outside dimensions:(LxW):64x38mm Material: 350gsm SBS对裱 Print: 1C (Pantone 1655C) Surface process: AQ Coating Other: Back side with Double sided tape (60x10mm) Remark:包装原料需符合FSC认证要求 | J6: 掛鉤 | K6: 1 | L6: 0.13994366 | M6: =L6*K6 -> 0.13994366 | P6: =W6-AH6 -> 0.0018792757 | Q6: 1 | R6: 0.934 | T6: 5000 | U6: =AF6 -> 14 | V6: 0.13342857 | W6: =V6*K6 -> 0.13342857 | X6: 5000 | Y6: =AJ6 -> 0 | Z6: =V6 -> 0.13342857 | AA6: =Z6*K6 -> 0.13342857 | AB6: =(M6-W6)/W6 -> 0.048828302 | AC6: 1 | AD6: 0.934 | AE6: 5000 | AF6: 14 | AG6: =AD6/$AJ$2 -> 0.1315493 | AH6: =AG6*K6 -> 0.1315493 | AI6: =(L6-AG6)/AG6 -> 0.063811563
A7: 3 | B7: 1 | C7: 5843-1053-00A0 | D7: CARDBOARD,ELM5 Gen2/FSG-E1J7,PAPER INSERT,KRAFT E FLUET,RoHS | E7: N/A | F7: paper insert | G7: material: E flute corrugated paper board, original color extension dimension：296x152mm | I7: Paper insert Outside dimensions:(LxWxD):318x154mm Material:E flute corrugated paper board, original color Process: Die-cut Remark:包装原料需符合FSC认证要求 | J7: 内纸卡 | K7: 1 | L7: 0.088715493 | M7: =L7*K7 -> 0.088715493 | N7: 031324: Paper with FSC certificate 鴻威測試OK | P7: =W7-AH7 -> 0.0017847082 | Q7: 1 | R7: 0.53 | T7: 5000 | U7: =AF7 -> 14 | V7: 0.075714286 | W7: =V7*K7 -> 0.075714286 | X7: 5000 | Z7: =V7 -> 0.075714286 | AA7: =Z7*K7 -> 0.075714286 | AB7: =(M7-W7)/W7 -> 0.17171406 | AC7: 1 | AD7: 0.5249 | AE7: 3000 | AF7: 14 | AG7: =AD7/$AJ$2 -> 0.073929577 | AH7: =AG7*K7 -> 0.073929577 | AI7: =(L7-AG7)/AG7 -> 0.2 | AJ7: difference between FSC and w/o FSC
A8: 4 | B8: 1 | C8: 5849-1053-04A0 | D8: LABEL,ELM5 Gen2/FSG-E1J7,BTS LABEL,RIVAL 3 GEN2,DIAMETER 30mm, TRANSPARENT WOOD PULP PAPER,RoHS | E8: N/A | F8: Seal label | J8: 封口贴 | K8: 1 | L8: 0.02 | M8: =L8*K8 -> 0.02 | P8: =W8-AH8 -> 0.0059 | Q8: 1 | R8: 0.1115 | T8: 10000 | U8: 21-28 | V8: 0.0159 | W8: =V8*K8 -> 0.0159 | X8: 10000 | Y8: 21-28 | Z8: =V8 -> 0.0159 | AA8: =Z8*K8 -> 0.0159 | AB8: =(M8-W8)/W8 -> 0.25786164 | AC8: 2 | AD8: 0.071 | AE8: 5000 | AF8: 14 | AG8: =AD8/$AJ$2 -> 0.01 | AH8: =AG8*K8 -> 0.01 | AI8: =(L8-AG8)/AG8 -> 1 | AJ8: 022724:true cost update
A9: 5 | B9: 1 | C9: 5831-1053-04A0 （global） 5831-1053-05A0（CA) | D9: MANUAL,ELM5 Gen2/FSG-E1J7,RIVAL3 GEN2,100x80mm,80GSM WFUC,FSC,RoHS | E9: N/A | F9: PIG | G9: material: 80g woodfree paper; dimension: 320 x 200 mm, printing: 2C double side printing type: folding paper | I9: Manual Flat sheet dimensions(LxW): (L)320*(W)200mm Fold size: 80*100mm Material : 80gsm WFUC Print: 2C double side printing Process: Folding X 4 Remark:包装原料需符合FSC认证要求 | J9: 说明书 | K9: 1 | L9: 0.12 | M9: =L9*K9 -> 0.12 | N9: 031324: Paper with FSC certificate was 0.0584 | P9: =W9-AH9 -> 0.00058148893 | Q9: 1 | R9: 0.289 | S9: 0.35 | T9: 5000 | U9: =AF9 -> 14 | V9: 0.041285714 | W9: =V9*K9 -> 0.041285714 | X9: 10000 | Y9: 21 | Z9: 0.12 | AA9: =Z9*K9 -> 0.12 | AB9: =(M9-W9)/W9 -> 1.9065744 | AC9: 1 | AD9: 0.289 | AE9: 5000 | AF9: 14 | AG9: =AD9/$AJ$2 -> 0.040704225 | AH9: =AG9*K9 -> 0.040704225 | AI9: =(L9-AG9)/AG9 -> 1.9480969 | AJ9: difference between FSC and w/o FSC
A10: 6 | B10: 1 | C10: 5845-1053-00A0 | D10: BAG,ELM5 Gen2/FSG-E1J7,PAPER SHEET,16GSM MG TISSUE PAPER,FSC,RoHS | E10: N/A | F10: PE bag for mouse | I10: Paper sheet Dimensions(LxW):(L)280x(W)220mm Material : 16gsm 雪梨纸 Print: N/A | J10: 雪梨紙（包鼠標) | K10: 2 | L10: 0.012 | M10: =L10*K10 -> 0.024 | P10: =W10-AH10 -> -0.30905433 | Q10: 2 | R10: 0.2 | T10: 5000 | U10: =AF10 -> 15 | V10: 0.028571429 | W10: =V10*K10 -> 0.057142857 | X10: 5000 | Y10: =AJ10 -> 0 | Z10: =V10 -> 0.028571429 | AA10: =Z10*K10 -> 0.057142857 | AB10: =(M10-W10)/W10 -> -0.58 | AC10: 1 | AD10: 1.3 | AE10: 10000 | AF10: 15 | AG10: =AD10/$AJ$2 -> 0.18309859 | AH10: =AG10*K10 -> 0.36619718 | AI10: =(L10-AG10)/AG10 -> -0.93446154
A11: 7 | B11: 1 | C11: 5842-1047-00AA | D11: CARTON,ELM5/FSG-E1J4,MASTER CARTON,182x149x178mm,KRAFT C FLUET,REMOVE SS LOGO,RoHS | E11: N/A | F11: Master Carton | G11: material: B flute, burst above 12KGF | I11: Carton Outside dimensions:(L)182X(W)149X(H)175mm; Material: A. Material type: Corrugated fibreboard B. Flute: C Flute C. Grade: 200# Mullen Burst OR 32 ECT Print: Black Joint: Glued inside Remark: 纸板原材料需符合FSC认证要求 | J11: 外箱 | K11: =1/6 -> 0.16666667 | L11: 0.32425352 | M11: =L11*K11 -> 0.054042254 | N11: 031324: Paper with FSC certificate | P11: =W11-AH11 -> -0.017654259 | Q11: 0.16666667 | R11: 1.15 | T11: 5000 | U11: =AF11 -> 15 | V11: 0.16428571 | W11: =V11*K11 -> 0.027380952 | X11: 10000 | Y11: 21 | Z11: 0.191 | AA11: =Z11*K11 -> 0.031833333 | AB11: =(M11-W11)/W11 -> 0.97371709 | AC11: 0.16666667 | AD11: 1.9185 | AE11: 500 | AF11: 15 | AG11: =AD11/$AJ$2 -> 0.27021127 | AH11: =AG11*K11 -> 0.045035211 | AI11: =(L11-AG11)/AG11 -> 0.2 | AJ11: difference between FSC and w/o FSC
A12: 8 | B12: 1 | C12: 5843-1047-01A0 | D12: CARDBOARD,ELM5/FSG-E1J4,T/B BOARD,171x138mm,KRAFT B FLUET,RoHS | E12: N/A | F12: carton TB board | G12: B/F, burst above 10KGF(inside the carton top and bottom) | I12: Paper board Dimension(LxW): (L)171x(W)138mm Material: B flute 12kgf Remark: 纸板原材料需符合FSC认证要求 | J12: 天地板 | K12: =2/6 -> 0.33333333 | L12: 0.088235294 | M12: =L12*K12 -> 0.029411765 | P12: =W12-AH12 -> 0.00011401744 | Q12: 0.33333333 | R12: 0.17 | T12: 5000 | U12: =AF12 -> 14 | V12: 0.024285714 | W12: =V12*K12 -> 0.0080952381 | X12: 10000 | Y12: 21 | Z12: 0.027 | AA12: =Z12*K12 -> 0.009 | AB12: =(M12-W12)/W12 -> 2.633218 | AC12: 0.33333333 | AD12: 0.17 | AE12: 500 | AF12: 14 | AG12: =AD12/$AJ$2 -> 0.023943662 | AH12: =AG12*K12 -> 0.0079812207 | AI12: =(L12-AG12)/AG12 -> 2.6851211
A13: 9 | B13: 1 | C13: 5831-1053-01A0 | D13: CARD,ELM5 Gen2/FSG-E1J7,PAPER FILM,16GSM MG TISSUE PAPER,PROTECTIVE FOR BOX,FSC,RoHS | E13: N/A | F13: Protective paper | I13: Protective paper Dimensions(LxW):(L)1092x(W)180mm Material : 16gsm 雪梨纸 Print: N/A | J13: 雪梨紙（包彩盒) | K13: 0.33333333 | L13: 0.0154 | M13: =L13*K13 -> 0.0051333333 | P13: =W13-AH13 -> -0.04167002 | Q13: 0.33333333 | R13: 0.38 | T13: 5000 | U13: =AF13 -> 28 | V13: 0.054285714 | W13: =V13*K13 -> 0.018095238 | X13: 5000 | Z13: =V13 -> 0.054285714 | AA13: =Z13*K13 -> 0.018095238 | AB13: =(M13-W13)/W13 -> -0.71631579 | AC13: 0.33333333 | AD13: 1.273 | AE13: 5000 | AF13: 28 | AG13: =AD13/$AJ$2 -> 0.17929577 | AH13: =AG13*K13 -> 0.059765258 | AI13: =(L13-AG13)/AG13 -> -0.91410841 | AJ13: 022724:true cost update
A14: 10 | B14: 1 | C14: 5849-1051-0AA0 | D14: LABEL,KINGPIN/FCG-3301,4"W x 6"L WHITE,PAPER LABEL,47-00034,RoHS | E14: N/A | F14: Label (for master carton) | G14: material: 80g art paper dimension：100x55 mm printing: 1C with online printing | I14: Master Carton Label Outside dimensions:(L)152X(W)102mm; Material : 80gsm artpaper Print: Black | J14: 外箱标签 | K14: =1/6 -> 0.16666667 | L14: 0.024264706 | M14: =L14*K14 -> 0.0040441176 | P14: =W14-AH14 -> 4.8960429e-05 | Q14: 0.16666667 | R14: 0.146 | T14: 5000 | U14: =AF14 -> 15 | V14: 0.020857143 | W14: =V14*K14 -> 0.0034761905 | X14: 5000 | Y14: =AJ14 -> 0 | Z14: =V14 -> 0.020857143 | AA14: =Z14*K14 -> 0.0034761905 | AB14: =(M14-W14)/W14 -> 0.16337631 | AC14: 0.16666667 | AD14: 0.146 | AE14: 5000 | AF14: 15 | AG14: =AD14/$AJ$2 -> 0.02056338 | AH14: =AG14*K14 -> 0.00342723 | AI14: =(L14-AG14)/AG14 -> 0.17999597
A15: 11 | B15: 1 | C15: 5849-1047-02A0 | D15: LABEL,ELM5/FSG-E1J4,MASTER CARTON SN LABEL,59.67x52mm,80GMS ARTPAPER,RoHS | E15: N/A | F15: S/N label for carton (for master carton) | G15: material: 80g art paper dimension：59.67x52 mm printing: blank with online printing | I15: Carton Label(SN) Outside dimensions: (L)59.67X(W)52mm; Material : 80gsm artpaper | J15: 外箱标签 | K15: =1/6 -> 0.16666667 | L15: 0.0097058824 | M15: =L15*K15 -> 0.0016176471 | P15: =W15-AH15 -> 1.9450034e-05 | Q15: 0.16666667 | R15: 0.058 | T15: 5000 | U15: =AF15 -> 15 | V15: 0.0082857143 | W15: =V15*K15 -> 0.0013809524 | X15: 5000 | Y15: =AJ15 -> 0 | Z15: =V15 -> 0.0082857143 | AA15: =Z15*K15 -> 0.0013809524 | AB15: =(M15-W15)/W15 -> 0.17139959 | AC15: 0.16666667 | AD15: 0.058 | AE15: 5000 | AF15: 15 | AG15: =AD15/$AJ$2 -> 0.0081690141 | AH15: =AG15*K15 -> 0.0013615023 | AI15: =(L15-AG15)/AG15 -> 0.18813387
A16: 12 | B16: 1 | C16: 5849-1047-01A0 | D16: LABEL,NINJA/FSG-E1J0,RETAIL BOX LABEL,38x12mm,80GMS ARTPAPER,BLANK,RoHS | E16: N/A | F16: SN Label (for color box) | G16: material: 80g art paper dimension: 38x12mm printing: blank with online printing | I16: Color box SN Label Outside dimensions: (L)38X(W)12mm; Material : 80gsm artpaper | J16: 彩盒标签 | K16: 1 | L16: 0.0056617647 | M16: =L16*K16 -> 0.0056617647 | P16: =W16-AH16 -> 2.0120724e-05 | Q16: 1 | R16: 0.01 | T16: 5000 | U16: =AF16 -> 15 | V16: 0.0014285714 | W16: =V16*K16 -> 0.0014285714 | X16: 5000 | Y16: =AJ16 -> 0 | Z16: =V16 -> 0.0014285714 | AA16: =Z16*K16 -> 0.0014285714 | AB16: =(M16-W16)/W16 -> 2.9632353 | AC16: 1 | AD16: 0.01 | AE16: 5000 | AF16: 15 | AG16: =AD16/$AJ$2 -> 0.0014084507 | AH16: =AG16*K16 -> 0.0014084507 | AI16: =(L16-AG16)/AG16 -> 3.0198529
A17: 13 | B17: 1 | C17: 5849-1053-02A0 黑色 5849-1053-03A0 白色 | D17: LABEL,ELM5 Gen2/FSG-E1J7,PID LABEL,62515 RIVAL 3 GEN2 BLACK,45.424x23mm, 50 PET WITH MATT PP,RoHS | E17: N/A | F17: PID label (for black product) | G17: material: 80g black PET+ printable matte pp film dimension:45.424x23 mm printing: 2C | I17: PID Label Outside dimensions: (L)45.424X(W)23mm; Material : 50#PET+25# PP film Print: 2C | J17: PID标签 | K17: 1 | L17: 0.08 | M17: =L17*K17 -> 0.08 | P17: =W17-AH17 -> 0.00030181087 | Q17: 1 | R17: 0.15 | T17: 10000 | U17: =AF17 -> 15 | V17: 0.021428571 | W17: =V17*K17 -> 0.021428571 | X17: 10000 | Y17: 21 | Z17: 0.08 | AA17: =Z17*K17 -> 0.08 | AB17: =(M17-W17)/W17 -> 2.7333333 | AC17: 1 | AD17: 0.15 | AE17: 5000 | AF17: 15 | AG17: =AD17/$AJ$2 -> 0.021126761 | AH17: =AG17*K17 -> 0.021126761 | AI17: =(L17-AG17)/AG17 -> 2.7866667 | AJ17: 022724:true cost update
A18: 14 | B18: 1 | C18: 5849-1012-05A0 | D18: LABEL,MICKEY,VK481AA ABA INNER CARTON LABEL 153*102mm,80GSM ARTPAPER,RoHS | E18: N/A | F18: Pallet label | G18: Label,Pallet,AP,153x102mm | H18: N/A | I18: Pallet Label Outside dimensions: (L)153X(W)102mm; Material : 80gsm artpaper | J18: 棧板标签 | K18: 0.001587 | L18: 0.026691176 | M18: =L18*K18 -> 4.2358897e-05 | P18: =W18-AH18 -> 4.3107646e-07 | Q18: 0.001587 | R18: 0.135 | T18: 5000 | U18: =AF18 -> 7 | V18: 0.019285714 | W18: =V18*K18 -> 3.0606429e-05 | X18: 5000 | Y18: =AJ18 -> 0 | Z18: =V18 -> 0.019285714 | AA18: =Z18*K18 -> 3.0606429e-05 | AB18: =(M18-W18)/W18 -> 0.38398693 | AC18: 0.0013333333 | AD18: 0.135 | AE18: 5000 | AF18: 7 | AG18: =AD18/$AJ$2 -> 0.019014085 | AH18: =AG18*K18 -> 3.0175352e-05 | AI18: =(L18-AG18)/AG18 -> 0.40375817
A19: 15 | B19: 1 | C19: 5849-1043-00A0 | D19: LABEL,NINJA/FSG-E1J0,LABEL FOR USB CABLE,66.4x15.3mm,80GMS ARTPAPER WITH MATTE PP FILM TWO SIDE,ADHESIVE,BLANK PRINGING,RoHS | E19: N/A | F19: Cable Tag | G19: material: 80g art paper, matte coating(with glue) dimension：66.073x15 mm printing: blank | I19: Cable tag Outside dimensions: (L)66.4X(W)15.3mm; Material : 80gsm artpaper, matte coating(with glue) | J19: USB標籤 | K19: 1 | L19: 0.0127 | M19: =L19*K19 -> 0.0127 | P19: =W19-AH19 -> 0.00014084507 | Q19: 1 | R19: 0.07 | T19: 5000 | U19: =AF19 -> 14 | V19: 0.01 | W19: =V19*K19 -> 0.01 | X19: 5000 | Y19: =AJ19 -> 0 | Z19: =V19 -> 0.01 | AA19: =Z19*K19 -> 0.01 | AB19: =(M19-W19)/W19 -> 0.27 | AC19: 1 | AD19: 0.07 | AE19: 5000 | AF19: 14 | AG19: =AD19/$AJ$2 -> 0.0098591549 | AH19: =AG19*K19 -> 0.0098591549 | AI19: =(L19-AG19)/AG19 -> 0.28814286
A20: 16 | B20: 1 | C20: 0981-53PN-00A0 | D20: PALLET,Hoist Gen2/FSG-E3J4,FLEX STYLE PALLET,1200x1000x130 mm,PLYWOOD,RoHS | E20: N/A | F20: Pallet & related | G20: pallet packing material Pallet | I20: PALLET,Hoist Gen2/FSG-E3J4,FLEX STYLE PALLET,1200x1000x130 mm,PLYWOOD,RoHS | J20: 膠合棧板 | K20: 0.000794 | L20: 15.71 | M20: =L20*K20 -> 0.01247374 | P20: =W20-AH20 -> -0.0028072773 | Q20: 0.000794 | R20: 76.8 | T20: 100 | U20: =AF20 -> 15 | V20: 10.971429 | W20: =V20*K20 -> 0.0087113143 | X20: 100 | Y20: =AJ20 -> 0 | Z20: =V20 -> 10.971429 | AA20: =Z20*K20 -> 0.0087113143 | AB20: =(M20-W20)/W20 -> 0.43190104 | AC20: 0.0013333333 | AD20: 103 | AE20: 100 | AF20: 15 | AG20: =AD20/$AJ$2 -> 14.507042 | AH20: =AG20*K20 -> 0.011518592 | AI20: =(L20-AG20)/AG20 -> 0.08292233
A21: 17 | B21: 1 | C21: 0984-001E-00A0 | D21: CARDBOARD,SLIP SHEET,CORRUGATED, B/C DOUBLEWALL, 1200MM X 1000MM,BC FLUTE,RoHS | E21: N/A | F21: Card Board | G21: N/A | H21: N/A | I21: Card Board Dimension: 1200x1000mm | J21: 隔板 | K21: =2/1260 -> 0.0015873016 | L21: 1.4041176 | M21: =L21*K21 -> 0.0022287582 | P21: =W21-AH21 -> 2.3186739e-05 | Q21: 0.0015873016 | R21: 7.26 | T21: 5000 | U21: =AF21 -> 14 | V21: 1.0371429 | W21: =V21*K21 -> 0.0016462585 | X21: 10000 | Y21: 21 | Z21: 1.2 | AA21: =Z21*K21 -> 0.0019047619 | AB21: =(M21-W21)/W21 -> 0.35383244 | AC21: 0.0015873016 | AD21: 7.26 | AE21: 100 | AF21: 14 | AG21: =AD21/$AJ$2 -> 1.0225352 | AH21: =AG21*K21 -> 0.0016230718 | AI21: =(L21-AG21)/AG21 -> 0.37317291
A22: 18 | B22: 1 | C22: 0984-1047-00A0 | D22: CARDBOARD,ELM5/FSG-E1J4,CORRUGATED, B FLUTE,1175x993 mm,RoHS | E22: N/A | F22: Card Board | G22: N/A | H22: N/A | I22: Card Board Dimension: 1175x993 mm | J22: 隔板 | K22: =4/1260 -> 0.0031746032 | L22: 0.48028169 | M22: =L22*K22 -> 0.0015247038 | P22: =W22-AH22 -> 2.1781483e-05 | Q22: 0.0031746032 | R22: 3.41 | T22: 1000 | U22: =AF22 -> 15 | V22: 0.48714286 | W22: =V22*K22 -> 0.0015464853 | X22: 10000 | Y22: 21 | Z22: 0.564 | AA22: =Z22*K22 -> 0.0017904762 | AB22: =(M22-W22)/W22 -> -0.014084507 | AC22: 0.0031746032 | AD22: 3.41 | AE22: 100 | AF22: 15 | AG22: =AD22/$AJ$2 -> 0.48028169 | AH22: =AG22*K22 -> 0.0015247038 | AI22: =(L22-AG22)/AG22 -> -2.3116081e-16 | AJ22: 022724:true cost update
A23: 19 | B23: 1 | C23: 0984-001H-00A0 | D23: CARDBOARD,PAPER ANGLE BEAD,1025X50X50mm,THICKNESS 5mm,KRAFT PAPER,RoHS | E23: N/A | F23: Corner Board | G23: N/A | H23: N/A | I23: Corner Board Dimension:1025X50X50mm | J23: 護角 | K23: 0.003175 | L23: 0.32676471 | M23: =L23*K23 -> 0.0010374779 | P23: =W23-AH23 -> 1.2904427e-05 | Q23: 0.003175 | R23: 2.02 | T23: 5000 | U23: =AF23 -> 15 | V23: 0.28857143 | W23: =V23*K23 -> 0.00091621429 | X23: 5000 | Y23: =AJ23 -> 0 | Z23: =V23 -> 0.28857143 | AA23: =Z23*K23 -> 0.00091621429 | AB23: =(M23-W23)/W23 -> 0.13235294 | AC23: 0.0063492063 | AD23: 2.02 | AE23: 1000 | AF23: 15 | AG23: =AD23/$AJ$2 -> 0.28450704 | AH23: =AG23*K23 -> 0.00090330986 | AI23: =(L23-AG23)/AG23 -> 0.14852941
A24: 20 | B24: 1 | C24: 0984-001J-00A0 | D24: CARDBOARD,PAPER ANGLE BEAD,900X50X50mm,THICKNESS 5mm,KRAFT PAPER,RoHS | E24: N/A | F24: Corner Board | G24: N/A | H24: N/A | I24: Corner Board Dimension:900X50X50mm | J24: 護角 | K24: 0.00635 | L24: 0.28632353 | M24: =L24*K24 -> 0.0018181544 | P24: =W24-AH24 -> 2.2614688e-05 | Q24: 0.00635 | R24: 1.77 | T24: 5000 | U24: =AF24 -> 15 | V24: 0.25285714 | W24: =V24*K24 -> 0.0016056429 | X24: 5000 | Y24: =AJ24 -> 0 | Z24: =V24 -> 0.25285714 | AA24: =Z24*K24 -> 0.0016056429 | AB24: =(M24-W24)/W24 -> 0.13235294 | AC24: 0.0031746032 | AD24: 1.77 | AE24: 1000 | AF24: 15 | AG24: =AD24/$AJ$2 -> 0.24929577 | AH24: =AG24*K24 -> 0.0015830282 | AI24: =(L24-AG24)/AG24 -> 0.14852941
A25: 21 | B25: 1 | C25: 0952-0004-0001 | D25: OC,DEPLETION,TAPE,SEAL,48mm*45m, | E25: N/A | F25: Seal tape_Clear | G25: N/A | H25: N/A | I25: OC,DEPLETION,TAPE,SEAL,48mm*45m, | J25: 透明封箱膠帶 | K25: 0.002222 | L25: 6.1352113 | M25: =L25*K25 -> 0.013632439 | P25: =W25-AH25 -> -0.0019116353 | Q25: 0.002222 | R25: 5.02 | T25: 100 | U25: =AF25 -> 15 | V25: 0.71714286 | W25: =V25*K25 -> 0.0015934914 | X25: 100 | Z25: =V25 -> 0.71714286 | AA25: =Z25*K25 -> 0.0015934914 | AB25: =(M25-W25)/W25 -> 7.5550755 | AC25: 0.005 | AD25: 11.2 | AE25: 900 | AF25: 15 | AG25: =AD25/$AJ$2 -> 1.5774648 | AH25: =AG25*K25 -> 0.0035051268 | AI25: =(L25-AG25)/AG25 -> 2.8892857 | AJ25: New
A26: 22 | B26: 1 | C26: 0952-0005-00E0 | D26: INK RIBBON,DEPLETION,B110A,110MM,LF | E26: N/A | F26: INK RIBBON | G26: N/A | H26: N/A | I26: INK RIBBON,DEPLETION,B110A,110MM,LF | J26: 碳带 | K26: 0.00103 | L26: 9.8873239 | M26: =L26*K26 -> 0.010183944 | P26: =W26-AH26 -> 0.00019480885 | Q26: 0.00103 | R26: 59 | T26: 10 | U26: =AF26 -> 7 | V26: 8.4285714 | W26: =V26*K26 -> 0.0086814286 | X26: 10 | Z26: =V26 -> 8.4285714 | AA26: =Z26*K26 -> 0.0086814286 | AB26: =(M26-W26)/W26 -> 0.17307233 | AC26: 0.000217 | AD26: 58.5 | AE26: 10 | AF26: 7 | AG26: =AD26/$AJ$2 -> 8.2394366 | AH26: =AG26*K26 -> 0.0084866197 | AI26: =(L26-AG26)/AG26 -> 0.2 | AJ26: New
A27: 23 | B27: 1 | C27: 0952-0002-00E0 | D27: INK RIBBON,DEPLETION,TW10,60MM,LF | E27: N/A | F27: INK RIBBON | G27: N/A | H27: N/A | I27: INK RIBBON,DEPLETION,TW10,60MM,LF | J27: 碳带 | K27: 0.000118 | L27: 5.3543662 | M27: =L27*K27 -> 0.00063181521 | P27: =W27-AH27 -> 1.2915895e-05 | Q27: 0.000118 | R27: 32 | T27: 10 | U27: =AF27 -> 7 | V27: 4.5714286 | W27: =V27*K27 -> 0.00053942857 | X27: 10 | Z27: =V27 -> 4.5714286 | AA27: =Z27*K27 -> 0.00053942857 | AB27: =(M27-W27)/W27 -> 0.17126761 | AC27: 0.000118 | AD27: 31.68 | AE27: 10 | AF27: 7 | AG27: =AD27/$AJ$2 -> 4.4619718 | AH27: =AG27*K27 -> 0.00052651268 | AI27: =(L27-AG27)/AG27 -> 0.2 | AJ27: New
A28: 24 | B28: 1 | C28: 0952-000N-00A0 | D28: INK RIBBON,DEPLETION,DMX480 BLACK,50MM*300M,RoHS | E28: N/A | F28: INK RIBBON | G28: N/A | H28: N/A | I28: INK RIBBON,DEPLETION,DMX480 BLACK,50MM*300M,RoHS | J28: 碳带 | K28: 0.0001 | L28: 7.6394366 | M28: =L28*K28 -> 0.00076394366 | P28: =W28-AH28 -> 0.00016338028 | Q28: 0.0001 | R28: 56 | T28: 10 | U28: =AF28 -> 7 | V28: 8 | W28: =V28*K28 -> 0.0008 | X28: 10 | Z28: =V28 -> 8 | AA28: =Z28*K28 -> 0.0008 | AB28: =(M28-W28)/W28 -> -0.045070423 | AC28: 0.0001 | AD28: 45.2 | AE28: 50 | AF28: 7 | AG28: =AD28/$AJ$2 -> 6.3661972 | AH28: =AG28*K28 -> 0.00063661972 | AI28: =(L28-AG28)/AG28 -> 0.2 | AJ28: New
A29: 25 | B29: 1 | C29: 0952-000S-00E0 | D29: OC,DEPLETION,TAPE,SEAL(400m*500mm*0.018cm),RoHS | E29: N/A | F29: Tape | G29: N/A | H29: N/A | I29: OC,DEPLETION,TAPE,SEAL(400m*500mm*0.018cm),RoHS | J29: 打包膜 | K29: 0.00045 | L29: 6.1352113 | M29: =L29*K29 -> 0.0027608451 | P29: =W29-AH29 -> 1.3581489e-05 | Q29: 0.00045 | R29: 36 | T29: 100 | U29: =AF29 -> 10 | V29: 5.1428571 | W29: =V29*K29 -> 0.0023142857 | X29: 100 | Z29: =V29 -> 5.1428571 | AA29: =Z29*K29 -> 0.0023142857 | AB29: =(M29-W29)/W29 -> 0.19295775 | AC29: 0.00045 | AD29: 36.3 | AE29: 500 | AF29: 10 | AG29: =AD29/$AJ$2 -> 5.1126761 | AH29: =AG29*K29 -> 0.0023007042 | AI29: =(L29-AG29)/AG29 -> 0.2 | AJ29: New
A30: 26 | B30: 1 | C30: 098C-1053-00A0 | D30: DESICCANT,ELM5 Gen2/FSG-E1J7,45X35MM-2G,RoHS | E30: N/A | F30: DESICCANT | G30: N/A | I30: DESICCANT Outside dimensions: (L)45X(W)35mm; Material : SiO2 乾燥劑, 2g/包 | J30: 乾燥劑 | K30: 1 | L30: 0.0085 | M30: =L30*K30 -> 0.0085 | P30: =W30-AH30 -> 0.007 | Q30: 1 | R30: 0.49 | T30: 15000 | U30: 14 | V30: 0.007 | W30: =V30*K30 -> 0.007 | X30: 15000 | Y30: 14 | Z30: =V30 -> 0.007 | AA30: =Z30*K30 -> 0.007 | AB30: =(M30-W30)/W30 -> 0.21428571 | AC30: 0.00045 | AD30: 36.3 | AE30: 500 | AF30: 10 | AH30: =AG30*K30 -> 0 | AI30: =(L30-AG30)/AG30 -> #DIV/0! | AJ30: New
A31: 27 | B31: 1 | C31: 0952-000T-00E0 | D31: TAPE,12mm*30y,LF | E31: N/A | F31: Tape | G31: N/A | H31: N/A | I31: TAPE,12mm*30y,LF | J31: 小膠帶 | K31: 0.002 | L31: 0 | M31: =L31*K31 -> 0 | P31: =W31-AH31 -> -0.010116781 | Q31: 0.002 | R31: 0.38 | T31: 1000 | U31: =AF31 -> 10 | V31: 0.054285714 | W31: =V31*K31 -> 0.00010857143 | X31: 1000 | Z31: =V31 -> 0.054285714 | AA31: =Z31*K31 -> 0.00010857143 | AB31: =(M31-W31)/W31 -> -1 | AC31: 0.00045 | AD31: 36.3 | AE31: 500 | AF31: 10 | AG31: =AD31/$AJ$2 -> 5.1126761 | AH31: =AG31*K31 -> 0.010225352 | AI31: =(L31-AG31)/AG31 -> -1 | AJ31: New
A32: Subtotal(USD/Unit)： | M32: =SUM(M5:M31) -> 0.94416822 | N32: 022724: ex rate 7.1 ex rate: 6.3 RMB | P32: =SUM(P22:P30) -> 0.0055303518 | W32: =SUM(W5:W31) -> 0.65310801 | AA32: =SUM(AA5:AA31) -> 0.79625336 | AB32: =(M32-W32)/W32 -> 0.44565401 | AG32: =AD32/$AJ$2 -> 0 | AH32: =SUM(AH22:AH29) -> 0.019466625 | AI32: =(M32-AH32)/AH32 -> 47.501896 | AJ32: Margin
A33: Subtotal(USD/Unit)： | N33: New ex rate 7 | AH33: -0.39967817 | AI33: -0.95355632 | AJ33: cost up due to FSC & sustainable material

Sheet PKG BOM 20241023_Amber
S1: 裕同 | T1: 旺盈
A2: Steelseries Rival3 Gen2 RFQ - Package BOM list | M2: Date: 2024/6/18 | R2: True Cost | Z2: True Cost | AG2: 7.1
A3: Model Description: Steelseries Rival 3 Gen2 | K3: Rev.:A | L3: ELM5 Gen2 | Q3: Difference between 1015 & 0618 | R3: 2024/10/14 DV Phase | S3: 報價 in RMB w/ FSC certificate | W3: 報價 in USD w/ FSC certificate | Y3: Markup | Z3: EV Phase | AA3: 報價 in RMB w/ FSC certificate | AD3: 報價 in USD w/ FSC certificate | AF3: Markup | AG3: Remark
A4: No. | B4: Level | C4: Foxlink P/N | D4: Foxlink P/N description | E4: Customer P/N | F4: Customer Description | H4: Image | I4: Description | J4: Chinese Part name | K4: Unit Q'ty (pcs) | L4: Unit Price (USD/pc) ELM5 Gen2 | M4: Amount (USD) ELM5 Gen2 | N4: Remark | R4: QTY | S4: 單價 RMB | T4: 單價 RMB | U4: MOQ | V4: LT day | W4: 單價 USD | X4: Amount(USD) | Z4: QTY | AA4: 單價 RMB | AB4: MOQ | AC4: LT day | AD4: 單價 USD | AE4: Amount(USD)
A5: 1 | B5: 1 | C5: 584A-1053-00A0 | D5: BOX,ELM5 Gen2/FSG-E1J7,62515 RIVAL3 GEN2 BLACK, 153x86x46mm,300gsm SBS,FSC,RoHS | E5: N/A | F5: black Box | G5: material: 300g artpaper, 4C+1C PMS, printing: matte PP dimension：278x250mm | I5: Box Outside set-up dimensions:(LxWxD):153x86x46mm Flat sheet dimensions:(L)278x(W)250x(T)0.5mm Material:350gsm SBS Print: 4C+1C PMS Surface process: AQ Coating Joint: Glued inside Remark:包装原料需符合FSC认证要求 | J5: 彩盒 | K5: 1 | L5: 0.3033 | M5: =L5*K5 -> 0.3033 | N5: 031324: Paper with FSC certificate was 0.2821 | Q5: =X5-AE5 -> 0.050704225 | R5: 1 | S5: 1.42 | T5: 1.4 | U5: 5000 | V5: =AC5 -> 14 | W5: =S5/$AG$2 -> 0.2 | X5: =W5*K5 -> 0.2 | Y5: =(M5-X5)/X5 -> 0.5165 | Z5: 1 | AA5: 1.06 | AB5: 5000 | AC5: 14 | AD5: =AA5/$AG$2 -> 0.14929577 | AE5: =AD5*K5 -> 0.14929577 | AF5: =(L5-AD5)/AD5 -> 1.0315377 | AG5: difference between FSC and w/o FSC
A6: 2 | C6: 5831-1053-00A0 | D6: CARD,ELM5 Gen2/FSG-E1J7,HANG TAB,350GSM SBS DOUBLE,AQ COATING,FSC,RoHS | E6: N/A | F6: Hanger | I6: Hang tab Outside dimensions:(LxW):64x38mm Material: 350gsm SBS对裱 Print: 1C (Pantone 1655C) Surface process: AQ Coating Other: Back side with Double sided tape (60x10mm) Remark:包装原料需符合FSC认证要求 | J6: 掛鉤 | K6: 1 | L6: 0.13994366 | M6: =L6*K6 -> 0.13994366 | Q6: =X6-AE6 -> 0 | R6: 1 | S6: 0.934 | U6: 5000 | V6: =AC6 -> 14 | W6: =S6/$AG$2 -> 0.1315493 | X6: =W6*K6 -> 0.1315493 | Y6: =(M6-X6)/X6 -> 0.063811563 | Z6: 1 | AA6: 0.934 | AB6: 5000 | AC6: 14 | AD6: =AA6/$AG$2 -> 0.1315493 | AE6: =AD6*K6 -> 0.1315493 | AF6: =(L6-AD6)/AD6 -> 0.063811563
A7: 3 | B7: 1 | C7: 5843-1053-00A0 | D7: CARDBOARD,ELM5 Gen2/FSG-E1J7,PAPER INSERT,KRAFT E FLUET,RoHS | E7: N/A | F7: paper insert | G7: material: E flute corrugated paper board, original color extension dimension：296x152mm | I7: Paper insert Outside dimensions:(LxWxD):318x154mm Material:E flute corrugated paper board, original color Process: Die-cut Remark:包装原料需符合FSC认证要求 | J7: 内纸卡 | K7: 1 | L7: =AD7*1.2 -> 0.088715493 | M7: =L7*K7 -> 0.088715493 | N7: 031324: Paper with FSC certificate 鴻威測試OK | Q7: =X7-AE7 -> 0.00071830986 | R7: 1 | S7: 0.53 | U7: 5000 | V7: =AC7 -> 14 | W7: =S7/$AG$2 -> 0.074647887 | X7: =W7*K7 -> 0.074647887 | Y7: =(M7-X7)/X7 -> 0.18845283 | Z7: 1 | AA7: 0.5249 | AB7: 3000 | AC7: 14 | AD7: =AA7/$AG$2 -> 0.073929577 | AE7: =AD7*K7 -> 0.073929577 | AF7: =(L7-AD7)/AD7 -> 0.2 | AG7: difference between FSC and w/o FSC
A8: 4 | B8: 1 | C8: 5849-1053-04A0 | D8: LABEL,ELM5 Gen2/FSG-E1J7,BTS LABEL,RIVAL 3 GEN2,DIAMETER 30mm, TRANSPARENT WOOD PULP PAPER,RoHS | E8: N/A | F8: Seal label | J8: 封口贴 | K8: 1 | L8: 0.02 | M8: =L8*K8 -> 0.02 | Q8: =X8-AE8 -> 0.0057042254 | R8: 1 | S8: 0.1115 | U8: 10000 | V8: 21-28 | W8: =S8/$AG$2 -> 0.015704225 | X8: =W8*K8 -> 0.015704225 | Y8: =(M8-X8)/X8 -> 0.2735426 | Z8: 2 | AA8: 0.071 | AB8: 5000 | AC8: 14 | AD8: =AA8/$AG$2 -> 0.01 | AE8: =AD8*K8 -> 0.01 | AF8: =(L8-AD8)/AD8 -> 1 | AG8: 022724:true cost update
A9: 5 | B9: 1 | C9: 5831-1053-02A0 | D9: MANUAL,ELM5 Gen2/FSG-E1J7,RIVAL3 GEN2,100x80mm,80GSM WFUC,FSC,RoHS | E9: N/A | F9: PIG | G9: material: 80g woodfree paper; dimension: 320 x 200 mm, printing: 2C double side printing type: folding paper | I9: Manual Flat sheet dimensions(LxW): (L)320*(W)200mm Fold size: 80*100mm Material : 80gsm WFUC Print: 2C double side printing Process: Folding X 4 Remark:包装原料需符合FSC认证要求 | J9: 说明书 | K9: 1 | L9: 0.0628 | M9: =L9*K9 -> 0.0628 | N9: 031324: Paper with FSC certificate was 0.0584 | Q9: =X9-AE9 -> 0 | R9: 1 | S9: 0.289 | T9: 0.35 | U9: 5000 | V9: =AC9 -> 14 | W9: =S9/$AG$2 -> 0.040704225 | X9: =W9*K9 -> 0.040704225 | Y9: =(M9-X9)/X9 -> 0.54283737 | Z9: 1 | AA9: 0.289 | AB9: 5000 | AC9: 14 | AD9: =AA9/$AG$2 -> 0.040704225 | AE9: =AD9*K9 -> 0.040704225 | AF9: =(L9-AD9)/AD9 -> 0.54283737 | AG9: difference between FSC and w/o FSC
A10: 6 | B10: 1 | C10: 5845-1053-00A0 | D10: BAG,ELM5 Gen2/FSG-E1J7,PAPER SHEET,16GSM MG TISSUE PAPER,FSC,RoHS | E10: N/A | F10: PE bag for mouse | I10: Paper sheet Dimensions(LxW):(L)280x(W)220mm Material : 16gsm 雪梨纸 Print: N/A | J10: 雪梨紙（包鼠標) | K10: 2 | L10: 0.012 | M10: =L10*K10 -> 0.024 | Q10: =X10-AE10 -> -0.30985915 | R10: 2 | S10: 0.2 | U10: 5000 | V10: =AC10 -> 15 | W10: =S10/$AG$2 -> 0.028169014 | X10: =W10*K10 -> 0.056338028 | Y10: =(M10-X10)/X10 -> -0.574 | Z10: 1 | AA10: 1.3 | AB10: 10000 | AC10: 15 | AD10: =AA10/$AG$2 -> 0.18309859 | AE10: =AD10*K10 -> 0.36619718 | AF10: =(L10-AD10)/AD10 -> -0.93446154
A11: 7 | B11: 1 | C11: 5842-1047-00AA | D11: CARTON,ELM5/FSG-E1J4,MASTER CARTON,182x149x178mm,KRAFT C FLUET,REMOVE SS LOGO,RoHS | E11: N/A | F11: Master Carton | G11: material: B flute, burst above 12KGF | I11: Carton Outside dimensions:(L)182X(W)149X(H)175mm; Material: A. Material type: Corrugated fibreboard B. Flute: C Flute C. Grade: 200# Mullen Burst OR 32 ECT Print: Black Joint: Glued inside Remark: 纸板原材料需符合FSC认证要求 | J11: 外箱 | K11: =1/6 -> 0.16666667 | L11: 0.32425352 | M11: =L11*K11 -> 0.054042254 | N11: 031324: Paper with FSC certificate | Q11: =X11-AE11 -> -0.018039906 | R11: 0.16666667 | S11: 1.15 | U11: 5000 | V11: =AC11 -> 15 | W11: =S11/$AG$2 -> 0.16197183 | X11: =W11*K11 -> 0.026995305 | Y11: =(M11-X11)/X11 -> 1.001913 | Z11: 0.16666667 | AA11: 1.9185 | AB11: 500 | AC11: 15 | AD11: =AA11/$AG$2 -> 0.27021127 | AE11: =AD11*K11 -> 0.045035211 | AF11: =(L11-AD11)/AD11 -> 0.2 | AG11: difference between FSC and w/o FSC
A12: 8 | B12: 1 | C12: 5843-1047-01A0 | D12: CARDBOARD,ELM5/FSG-E1J4,T/B BOARD,171x138mm,KRAFT B FLUET,RoHS | E12: N/A | F12: carton TB board | G12: B/F, burst above 10KGF(inside the carton top and bottom) | I12: Paper board Dimension(LxW): (L)171x(W)138mm Material: B flute 12kgf Remark: 纸板原材料需符合FSC认证要求 | J12: 天地板 | K12: =2/6 -> 0.33333333 | L12: 0.088235294 | M12: =L12*K12 -> 0.029411765 | Q12: =X12-AE12 -> 0 | R12: 0.33333333 | S12: 0.17 | U12: 5000 | V12: =AC12 -> 14 | W12: =S12/$AG$2 -> 0.023943662 | X12: =W12*K12 -> 0.0079812207 | Y12: =(M12-X12)/X12 -> 2.6851211 | Z12: 0.33333333 | AA12: 0.17 | AB12: 500 | AC12: 14 | AD12: =AA12/$AG$2 -> 0.023943662 | AE12: =AD12*K12 -> 0.0079812207 | AF12: =(L12-AD12)/AD12 -> 2.6851211
A13: 9 | B13: 1 | C13: 5831-1053-01A0 | D13: CARD,ELM5 Gen2/FSG-E1J7,PAPER FILM,16GSM MG TISSUE PAPER,PROTECTIVE FOR BOX,FSC,RoHS | E13: N/A | F13: Protective paper | I13: Protective paper Dimensions(LxW):(L)1092x(W)180mm Material : 16gsm 雪梨纸 Print: N/A | J13: 雪梨紙（包彩盒) | K13: 0.33333333 | L13: 0.0154 | M13: =L13*K13 -> 0.0051333333 | Q13: =X13-AE13 -> -0.041924883 | R13: 0.33333333 | S13: 0.38 | U13: 5000 | V13: =AC13 -> 28 | W13: =S13/$AG$2 -> 0.053521127 | X13: =W13*K13 -> 0.017840376 | Y13: =(M13-X13)/X13 -> -0.71226316 | Z13: 0.33333333 | AA13: 1.273 | AB13: 5000 | AC13: 28 | AD13: =AA13/$AG$2 -> 0.17929577 | AE13: =AD13*K13 -> 0.059765258 | AF13: =(L13-AD13)/AD13 -> -0.91410841 | AG13: 022724:true cost update
A14: 10 | B14: 1 | C14: 5849-1051-0AA0 | D14: LABEL,KINGPIN/FCG-3301,4"W x 6"L WHITE,PAPER LABEL,47-00034,RoHS | E14: N/A | F14: Label (for master carton) | G14: material: 80g art paper dimension：100x55 mm printing: 1C with online printing | I14: Master Carton Label Outside dimensions:(L)152X(W)102mm; Material : 80gsm artpaper Print: Black | J14: 外箱标签 | K14: =1/6 -> 0.16666667 | L14: 0.024264706 | M14: =L14*K14 -> 0.0040441176 | Q14: =X14-AE14 -> 0 | R14: 0.16666667 | S14: 0.146 | U14: 5000 | V14: =AC14 -> 15 | W14: =S14/$AG$2 -> 0.02056338 | X14: =W14*K14 -> 0.00342723 | Y14: =(M14-X14)/X14 -> 0.17999597 | Z14: 0.16666667 | AA14: 0.146 | AB14: 5000 | AC14: 15 | AD14: =AA14/$AG$2 -> 0.02056338 | AE14: =AD14*K14 -> 0.00342723 | AF14: =(L14-AD14)/AD14 -> 0.17999597
A15: 11 | B15: 1 | C15: 5849-1047-02A0 | D15: LABEL,ELM5/FSG-E1J4,MASTER CARTON SN LABEL,59.67x52mm,80GMS ARTPAPER,RoHS | E15: N/A | F15: S/N label for carton (for master carton) | G15: material: 80g art paper dimension：59.67x52 mm printing: blank with online printing | I15: Carton Label(SN) Outside dimensions: (L)59.67X(W)52mm; Material : 80gsm artpaper | J15: 外箱标签 | K15: =1/6 -> 0.16666667 | L15: 0.0097058824 | M15: =L15*K15 -> 0.0016176471 | Q15: =X15-AE15 -> 0 | R15: 0.16666667 | S15: 0.058 | U15: 5000 | V15: =AC15 -> 15 | W15: =S15/$AG$2 -> 0.0081690141 | X15: =W15*K15 -> 0.0013615023 | Y15: =(M15-X15)/X15 -> 0.18813387 | Z15: 0.16666667 | AA15: 0.058 | AB15: 5000 | AC15: 15 | AD15: =AA15/$AG$2 -> 0.0081690141 | AE15: =AD15*K15 -> 0.0013615023 | AF15: =(L15-AD15)/AD15 -> 0.18813387
A16: 12 | B16: 1 | C16: 5849-1047-01A0 | D16: LABEL,NINJA/FSG-E1J0,RETAIL BOX LABEL,38x12mm,80GMS ARTPAPER,BLANK,RoHS | E16: N/A | F16: SN Label (for color box) | G16: material: 80g art paper dimension: 38x12mm printing: blank with online printing | I16: Color box SN Label Outside dimensions: (L)38X(W)12mm; Material : 80gsm artpaper | J16: 彩盒标签 | K16: 1 | L16: 0.0056617647 | M16: =L16*K16 -> 0.0056617647 | Q16: =X16-AE16 -> 0 | R16: 1 | S16: 0.01 | U16: 5000 | V16: =AC16 -> 15 | W16: =S16/$AG$2 -> 0.0014084507 | X16: =W16*K16 -> 0.0014084507 | Y16: =(M16-X16)/X16 -> 3.0198529 | Z16: 1 | AA16: 0.01 | AB16: 5000 | AC16: 15 | AD16: =AA16/$AG$2 -> 0.0014084507 | AE16: =AD16*K16 -> 0.0014084507 | AF16: =(L16-AD16)/AD16 -> 3.0198529
A17: 13 | B17: 1 | C17: 5849-1053-00A0 | D17: LABEL,ELM5 Gen2/FSG-E1J7,PID LABEL,62515 RIVAL 3 GEN2 BLACK,45.424x23mm, 50 PET WITH MATT PP,RoHS | E17: N/A | F17: PID label (for black product) | G17: material: 80g black PET+ printable matte pp film dimension:45.424x23 mm printing: 2C | I17: PID Label Outside dimensions: (L)45.424X(W)23mm; Material : 50#PET+25# PP film Print: 2C | J17: PID标签 | K17: 1 | L17: 0.021126761 | M17: =L17*K17 -> 0.021126761 | Q17: =X17-AE17 -> 0 | R17: 1 | S17: 0.15 | U17: 10000 | V17: =AC17 -> 15 | W17: =S17/$AG$2 -> 0.021126761 | X17: =W17*K17 -> 0.021126761 | Y17: =(M17-X17)/X17 -> 8.2110245e-16 | Z17: 1 | AA17: 0.15 | AB17: 5000 | AC17: 15 | AD17: =AA17/$AG$2 -> 0.021126761 | AE17: =AD17*K17 -> 0.021126761 | AF17: =(L17-AD17)/AD17 -> 8.2110245e-16 | AG17: 022724:true cost update
A18: 14 | B18: 1 | C18: 5849-1012-05A0 | D18: LABEL,MICKEY,VK481AA ABA INNER CARTON LABEL 153*102mm,80GSM ARTPAPER,RoHS | E18: N/A | F18: Pallet label | G18: Label,Pallet,AP,153x102mm | H18: N/A | I18: Pallet Label Outside dimensions: (L)153X(W)102mm; Material : 80gsm artpaper | J18: 棧板标签 | K18: 0.001587 | L18: 0.026691176 | M18: =L18*K18 -> 4.2358897e-05 | Q18: =X18-AE18 -> 0 | R18: 0.001587 | S18: 0.135 | U18: 5000 | V18: =AC18 -> 7 | W18: =S18/$AG$2 -> 0.019014085 | X18: =W18*K18 -> 3.0175352e-05 | Y18: =(M18-X18)/X18 -> 0.40375817 | Z18: 0.0013333333 | AA18: 0.135 | AB18: 5000 | AC18: 7 | AD18: =AA18/$AG$2 -> 0.019014085 | AE18: =AD18*K18 -> 3.0175352e-05 | AF18: =(L18-AD18)/AD18 -> 0.40375817
A19: 15 | B19: 1 | C19: 5849-1043-00A0 | D19: LABEL,NINJA/FSG-E1J0,LABEL FOR USB CABLE,66.4x15.3mm,80GMS ARTPAPER WITH MATTE PP FILM TWO SIDE,ADHESIVE,BLANK PRINGING,RoHS | E19: N/A | F19: Cable Tag | G19: material: 80g art paper, matte coating(with glue) dimension：66.073x15 mm printing: blank | I19: Cable tag Outside dimensions: (L)66.4X(W)15.3mm; Material : 80gsm artpaper, matte coating(with glue) | J19: USB標籤 | K19: 1 | L19: 0.0127 | M19: =L19*K19 -> 0.0127 | Q19: =X19-AE19 -> 0 | R19: 1 | S19: 0.07 | U19: 5000 | V19: =AC19 -> 14 | W19: =S19/$AG$2 -> 0.0098591549 | X19: =W19*K19 -> 0.0098591549 | Y19: =(M19-X19)/X19 -> 0.28814286 | Z19: 1 | AA19: 0.07 | AB19: 5000 | AC19: 14 | AD19: =AA19/$AG$2 -> 0.0098591549 | AE19: =AD19*K19 -> 0.0098591549 | AF19: =(L19-AD19)/AD19 -> 0.28814286
A20: 16 | B20: 1 | C20: 0981-53PN-00A0 | D20: PALLET,Hoist Gen2/FSG-E3J4,FLEX STYLE PALLET,1200x1000x130 mm,PLYWOOD,RoHS | E20: N/A | F20: Pallet & related | G20: pallet packing material Pallet | I20: PALLET,Hoist Gen2/FSG-E3J4,FLEX STYLE PALLET,1200x1000x130 mm,PLYWOOD,RoHS | J20: 膠合棧板 | K20: 0.000794 | L20: 15.71 | M20: =L20*K20 -> 0.01247374 | Q20: =X20-AE20 -> -0.0029299718 | R20: 0.000794 | S20: 76.8 | U20: 100 | V20: =AC20 -> 15 | W20: =S20/$AG$2 -> 10.816901 | X20: =W20*K20 -> 0.0085886197 | Y20: =(M20-X20)/X20 -> 0.45235677 | Z20: 0.0013333333 | AA20: 103 | AB20: 100 | AC20: 15 | AD20: =AA20/$AG$2 -> 14.507042 | AE20: =AD20*K20 -> 0.011518592 | AF20: =(L20-AD20)/AD20 -> 0.08292233
A21: 17 | B21: 1 | C21: 0984-001E-00A0 | D21: CARDBOARD,SLIP SHEET,CORRUGATED, B/C DOUBLEWALL, 1200MM X 1000MM,BC FLUTE,RoHS | E21: N/A | F21: Card Board | G21: N/A | H21: N/A | I21: Card Board Dimension: 1200x1000mm | J21: 隔板 | K21: =2/1260 -> 0.0015873016 | L21: 1.4041176 | M21: =L21*K21 -> 0.0022287582 | Q21: =X21-AE21 -> 0 | R21: 0.0015873016 | S21: 7.26 | U21: 5000 | V21: =AC21 -> 14 | W21: =S21/$AG$2 -> 1.0225352 | X21: =W21*K21 -> 0.0016230718 | Y21: =(M21-X21)/X21 -> 0.37317291 | Z21: 0.0015873016 | AA21: 7.26 | AB21: 100 | AC21: 14 | AD21: =AA21/$AG$2 -> 1.0225352 | AE21: =AD21*K21 -> 0.0016230718 | AF21: =(L21-AD21)/AD21 -> 0.37317291
A22: 18 | B22: 1 | C22: 0984-1047-00A0 | D22: CARDBOARD,ELM5/FSG-E1J4,CORRUGATED, B FLUTE,1175x993 mm,RoHS | E22: N/A | F22: Card Board | G22: N/A | H22: N/A | I22: Card Board Dimension: 1175x993 mm | J22: 隔板 | K22: =4/1260 -> 0.0031746032 | L22: 0.48028169 | M22: =L22*K22 -> 0.0015247038 | Q22: =X22-AE22 -> 0 | R22: 0.0031746032 | S22: 3.41 | U22: 5000 | V22: =AC22 -> 15 | W22: =S22/$AG$2 -> 0.48028169 | X22: =W22*K22 -> 0.0015247038 | Y22: =(M22-X22)/X22 -> -2.8443615e-16 | Z22: 0.0031746032 | AA22: 3.41 | AB22: 100 | AC22: 15 | AD22: =AA22/$AG$2 -> 0.48028169 | AE22: =AD22*K22 -> 0.0015247038 | AF22: =(L22-AD22)/AD22 -> -2.3116081e-16 | AG22: 022724:true cost update
A23: 19 | B23: 1 | C23: 0984-001H-00A0 | D23: CARDBOARD,PAPER ANGLE BEAD,1025X50X50mm,THICKNESS 5mm,KRAFT PAPER,RoHS | E23: N/A | F23: Corner Board | G23: N/A | H23: N/A | I23: Corner Board Dimension:1025X50X50mm | J23: 護角 | K23: 0.003175 | L23: 0.32676471 | M23: =L23*K23 -> 0.0010374779 | Q23: =X23-AE23 -> 0 | R23: 0.003175 | S23: 2.02 | U23: 5000 | V23: =AC23 -> 15 | W23: =S23/$AG$2 -> 0.28450704 | X23: =W23*K23 -> 0.00090330986 | Y23: =(M23-X23)/X23 -> 0.14852941 | Z23: 0.0063492063 | AA23: 2.02 | AB23: 1000 | AC23: 15 | AD23: =AA23/$AG$2 -> 0.28450704 | AE23: =AD23*K23 -> 0.00090330986 | AF23: =(L23-AD23)/AD23 -> 0.14852941
A24: 20 | B24: 1 | C24: 0984-001J-00A0 | D24: CARDBOARD,PAPER ANGLE BEAD,900X50X50mm,THICKNESS 5mm,KRAFT PAPER,RoHS | E24: N/A | F24: Corner Board | G24: N/A | H24: N/A | I24: Corner Board Dimension:900X50X50mm | J24: 護角 | K24: 0.00635 | L24: 0.28632353 | M24: =L24*K24 -> 0.0018181544 | Q24: =X24-AE24 -> 0 | R24: 0.00635 | S24: 1.77 | U24: 5000 | V24: =AC24 -> 15 | W24: =S24/$AG$2 -> 0.24929577 | X24: =W24*K24 -> 0.0015830282 | Y24: =(M24-X24)/X24 -> 0.14852941 | Z24: 0.0031746032 | AA24: 1.77 | AB24: 1000 | AC24: 15 | AD24: =AA24/$AG$2 -> 0.24929577 | AE24: =AD24*K24 -> 0.0015830282 | AF24: =(L24-AD24)/AD24 -> 0.14852941
A25: 21 | B25: 1 | C25: 0952-0004-0001 | D25: OC,DEPLETION,TAPE,SEAL,48mm*45m, | E25: N/A | F25: Seal tape_Clear | G25: N/A | H25: N/A | I25: OC,DEPLETION,TAPE,SEAL,48mm*45m, | J25: 透明封箱膠帶 | K25: 0.002222 | L25: 6.1352113 | M25: =L25*K25 -> 0.013632439 | Q25: =X25-AE25 -> -0.0019340789 | R25: 0.002222 | S25: 5.02 | U25: 100 | V25: =AC25 -> 15 | W25: =S25/$AG$2 -> 0.70704225 | X25: =W25*K25 -> 0.0015710479 | Y25: =(M25-X25)/X25 -> 7.6772908 | Z25: 0.005 | AA25: 11.2 | AB25: 900 | AC25: 15 | AD25: =AA25/$AG$2 -> 1.5774648 | AE25: =AD25*K25 -> 0.0035051268 | AF25: =(L25-AD25)/AD25 -> 2.8892857 | AG25: New
